<?xml version="1.0" ?>
<!-- Generated using onshape-to-robot -->
<!-- Onshape https://cad.onshape.com/documents/e803f61fd7378df7db81a183/w/36ce3c529374e351e627bf1e/e/ae663fd50540cead502d899d -->
<robot name="foosball_robot">
  <!-- Link main_body -->
  <link name="main_body">
    <inertial>
      <origin xyz="-1.50098e-14 6.28733e-17 0.0622025" rpy="0 0 0"/>
      <mass value="4.72465"/>
      <inertia ixx="0.134376" ixy="0" ixz="-1.81579e-12" iyy="0.20079" iyz="1.41662e-16" izz="0.30924"/>
    </inertial>
    <!-- Part main_body -->
    <visual>
      <origin xyz="-1.38778e-17 0 0.01" rpy="0 -0 0"/>
      <geometry>
        <mesh filename="package://assets/main_body.stl"/>
      </geometry>
      <material name="main_body_material">
        <color rgba="0.721569 0.678431 0.54902 1"/>
      </material>
    </visual>
    <collision>
      <origin xyz="-1.38778e-17 0 0.01" rpy="0 -0 0"/>
      <geometry>
        <mesh filename="package://assets/main_body.stl"/>
      </geometry>
    </collision>
  </link>
  <!-- Link rod -->
  <link name="rod">
    <inertial>
      <origin xyz="-1.38778e-17 0 -0.45" rpy="0 0 0"/>
      <mass value="0.688975"/>
      <inertia ixx="0.0465213" ixy="6.94252e-76" ixz="0" iyy="0.0465213" iyz="-2.7229e-50" izz="3.109e-05"/>
    </inertial>
    <!-- Part rod -->
    <visual>
      <origin xyz="-0.0414993 -0.0452426 -0.45" rpy="-1.5708 -0 1.49233e-74"/>
      <geometry>
        <mesh filename="package://assets/rod.stl"/>
      </geometry>
      <material name="rod_material">
        <color rgba="0.647059 0.647059 0.647059 1"/>
      </material>
    </visual>
    <collision>
      <origin xyz="-0.0414993 -0.0452426 -0.45" rpy="-1.5708 -0 1.49233e-74"/>
      <geometry>
        <mesh filename="package://assets/rod.stl"/>
      </geometry>
    </collision>
  </link>
  <!-- Link player -->
  <link name="player">
    <inertial>
      <origin xyz="2.66961e-17 0.0188179 1.5804e-17" rpy="0 0 0"/>
      <mass value="0.154321"/>
      <inertia ixx="0.000209611" ixy="-1.68583e-20" ixz="4.47461e-47" iyy="4.81083e-05" iyz="-3.18561e-47" izz="0.000210579"/>
    </inertial>
    <!-- Part player -->
    <visual>
      <origin xyz="2.77556e-17 0.1 2.77556e-17" rpy="1.5708 -2.15215e-43 -8.54097e-17"/>
      <geometry>
        <mesh filename="package://assets/player.stl"/>
      </geometry>
      <material name="player_material">
        <color rgba="0.866667 0.321569 0.156863 1"/>
      </material>
    </visual>
    <collision>
      <origin xyz="2.77556e-17 0.1 2.77556e-17" rpy="1.5708 -2.15215e-43 -8.54097e-17"/>
      <geometry>
        <mesh filename="package://assets/player.stl"/>
      </geometry>
    </collision>
  </link>
  <!-- Joint from rod to player -->
  <joint name="kicker" type="revolute">
    <origin xyz="-2.77556e-17 5.55112e-17 -0.45" rpy="3.14159 2.13707e-27 -0.785315"/>
    <parent link="rod"/>
    <child link="player"/>
    <axis xyz="0 0 1"/>
    <limit effort="10" velocity="10" lower="-3.141592653589793" upper="3.141592653589793"/>
  </joint>
  <!-- Joint from main_body to rod -->
  <joint name="slider" type="prismatic">
    <origin xyz="-0.172 -0.296 0.12" rpy="1.5708 -0 -1.81068e-29"/>
    <parent link="main_body"/>
    <child link="rod"/>
    <axis xyz="0 0 1"/>
    <limit effort="10" velocity="10" lower="0" upper="0.308"/>
  </joint>
  <!-- Link rod_2 -->
  <link name="rod_2">
    <inertial>
      <origin xyz="1.38778e-17 0 -0.45" rpy="0 0 0"/>
      <mass value="0.688975"/>
      <inertia ixx="0.0465213" ixy="0" ixz="1.63172e-37" iyy="0.0465213" iyz="0" izz="3.109e-05"/>
    </inertial>
    <!-- Part rod_2 -->
    <visual>
      <origin xyz="-0.0414993 -0.0452426 -0.45" rpy="-1.5708 -3.5098e-36 0"/>
      <geometry>
        <mesh filename="package://assets/rod.stl"/>
      </geometry>
      <material name="rod_2_material">
        <color rgba="0.647059 0.647059 0.647059 1"/>
      </material>
    </visual>
    <collision>
      <origin xyz="-0.0414993 -0.0452426 -0.45" rpy="-1.5708 -3.5098e-36 0"/>
      <geometry>
        <mesh filename="package://assets/rod.stl"/>
      </geometry>
    </collision>
  </link>
  <!-- Link player_2 -->
  <link name="player_2">
    <inertial>
      <origin xyz="2.86896e-20 0.0188179 1.62377e-17" rpy="0 0 0"/>
      <mass value="0.154321"/>
      <inertia ixx="0.000209611" ixy="-5.10115e-21" ixz="3.06951e-36" iyy="4.81083e-05" iyz="-8.71709e-36" izz="0.000210579"/>
    </inertial>
    <!-- Part player_2 -->
    <visual>
      <origin xyz="0 0.1 2.81893e-17" rpy="1.5708 3.05743e-34 -2.62428e-17"/>
      <geometry>
        <mesh filename="package://assets/player.stl"/>
      </geometry>
      <material name="player_2_material">
        <color rgba="0.866667 0.321569 0.156863 1"/>
      </material>
    </visual>
    <collision>
      <origin xyz="0 0.1 2.81893e-17" rpy="1.5708 3.05743e-34 -2.62428e-17"/>
      <geometry>
        <mesh filename="package://assets/player.stl"/>
      </geometry>
    </collision>
  </link>
  <!-- Joint from rod_2 to player_2 -->
  <joint name="opponent_kicker" type="revolute">
    <origin xyz="8.32667e-17 6.93889e-17 -0.45" rpy="3.14159 -2.34268e-31 -2.55449"/>
    <parent link="rod_2"/>
    <child link="player_2"/>
    <axis xyz="0 0 1"/>
    <limit effort="10" velocity="10" lower="-3.141592653589793" upper="3.141592653589793"/>
  </joint>
  <!-- Joint from main_body to rod_2 -->
  <joint name="opponent_slider" type="prismatic">
    <origin xyz="0.172 -0.453029 0.12" rpy="1.5708 -3.99333e-20 2.92256e-16"/>
    <parent link="main_body"/>
    <child link="rod_2"/>
    <axis xyz="0 0 1"/>
    <limit effort="10" velocity="10" lower="-0.157029" upper="0.150971"/>
  </joint>
</robot>
