<?xml version="1.0" ?>
<!-- Generated using onshape-to-robot -->
<!-- Onshape https://cad.onshape.com/documents/e803f61fd7378df7db81a183/w/36ce3c529374e351e627bf1e/e/ae663fd50540cead502d899d -->
<robot name="foosball_robot">
  <!-- Link main_body -->
  <link name="main_body">
    <inertial>
      <origin xyz="-1.4992e-14 5.4428e-17 0.0622025" rpy="0 0 0"/>
      <mass value="4.72465"/>
      <inertia ixx="0.134376" ixy="0" ixz="-1.81579e-12" iyy="0.20079" iyz="1.42284e-16" izz="0.30924"/>
    </inertial>
    <!-- Part main_body -->
    <visual>
      <origin xyz="-1.38778e-17 0 0.01" rpy="0 -0 0"/>
      <geometry>
        <mesh filename="package://assets/main_body.stl"/>
      </geometry>
      <material name="main_body_material">
        <color rgba="0.721569 0.678431 0.54902 1"/>
      </material>
    </visual>
    <collision>
      <origin xyz="-1.38778e-17 0 0.01" rpy="0 -0 0"/>
      <geometry>
        <mesh filename="package://assets/main_body.stl"/>
      </geometry>
    </collision>
  </link>
  <!-- Link rod -->
  <link name="rod">
    <inertial>
      <origin xyz="-1.38778e-17 0 -0.45" rpy="0 0 0"/>
      <mass value="0.688975"/>
      <inertia ixx="0.0465213" ixy="3.3509e-44" ixz="0" iyy="0.0465213" iyz="0" izz="3.109e-05"/>
    </inertial>
    <!-- Part rod -->
    <visual>
      <origin xyz="-0.0414993 -0.0452426 -0.45" rpy="-1.5708 -0 3.60146e-43"/>
      <geometry>
        <mesh filename="package://assets/rod.stl"/>
      </geometry>
      <material name="rod_material">
        <color rgba="0.647059 0.647059 0.647059 1"/>
      </material>
    </visual>
    <collision>
      <origin xyz="-0.0414993 -0.0452426 -0.45" rpy="-1.5708 -0 3.60146e-43"/>
      <geometry>
        <mesh filename="package://assets/rod.stl"/>
      </geometry>
    </collision>
  </link>
  <!-- Link player -->
  <link name="player">
    <inertial>
      <origin xyz="6.84524e-19 0.0188179 1.58252e-17" rpy="0 0 0"/>
      <mass value="0.154321"/>
      <inertia ixx="0.000209611" ixy="1.28644e-62" ixz="0" iyy="4.81083e-05" iyz="0" izz="0.000210579"/>
    </inertial>
    <!-- Part player -->
    <visual>
      <origin xyz="0 0.1 2.77556e-17" rpy="1.5708 -0 7.96546e-59"/>
      <geometry>
        <mesh filename="package://assets/player.stl"/>
      </geometry>
      <material name="player_material">
        <color rgba="0.866667 0.321569 0.156863 1"/>
      </material>
    </visual>
    <collision>
      <origin xyz="0 0.1 2.77556e-17" rpy="1.5708 -0 7.96546e-59"/>
      <geometry>
        <mesh filename="package://assets/player.stl"/>
      </geometry>
    </collision>
  </link>
  <!-- Joint from rod to player -->
  <joint name="kicker" type="continuous">
    <origin xyz="-2.77556e-17 6.93889e-17 -0.45" rpy="3.14159 0 0"/>
    <parent link="rod"/>
    <child link="player"/>
    <axis xyz="0 0 1"/>
    <limit effort="100" velocity="170"/>
  </joint>
  <!-- Joint from main_body to rod -->
  <joint name="slider" type="prismatic">
    <origin xyz="-0.172 -0.45 0.12" rpy="1.5708 -1.60236e-18 -2.18272e-28"/>
    <parent link="main_body"/>
    <child link="rod"/>
    <axis xyz="0 0 1"/>
    <limit effort="100" velocity="15" lower="-0.154" upper="0.154"/>
  </joint>
  <!-- Link rod_2 -->
  <link name="rod_2">
    <inertial>
      <origin xyz="-1.38778e-17 0 -0.45" rpy="0 0 0"/>
      <mass value="0.688975"/>
      <inertia ixx="0.0465213" ixy="8.32375e-80" ixz="-6.3231e-144" iyy="0.0465213" iyz="3.53397e-66" izz="3.109e-05"/>
    </inertial>
    <!-- Part rod_2 -->
    <visual>
      <origin xyz="-0.0414993 -0.0452426 -0.45" rpy="-1.5708 -0 3.57846e-78"/>
      <geometry>
        <mesh filename="package://assets/rod.stl"/>
      </geometry>
      <material name="rod_2_material">
        <color rgba="0.647059 0.647059 0.647059 1"/>
      </material>
    </visual>
    <collision>
      <origin xyz="-0.0414993 -0.0452426 -0.45" rpy="-1.5708 -0 3.57846e-78"/>
      <geometry>
        <mesh filename="package://assets/rod.stl"/>
      </geometry>
    </collision>
  </link>
  <!-- Link player_2 -->
  <link name="player_2">
    <inertial>
      <origin xyz="6.84524e-19 0.0188179 1.58252e-17" rpy="0 0 0"/>
      <mass value="0.154321"/>
      <inertia ixx="0.000209611" ixy="1.70177e-78" ixz="0" iyy="4.81083e-05" iyz="0" izz="0.000210579"/>
    </inertial>
    <!-- Part player_2 -->
    <visual>
      <origin xyz="0 0.1 2.77556e-17" rpy="1.5708 -0 0"/>
      <geometry>
        <mesh filename="package://assets/player.stl"/>
      </geometry>
      <material name="player_2_material">
        <color rgba="0.866667 0.321569 0.156863 1"/>
      </material>
    </visual>
    <collision>
      <origin xyz="0 0.1 2.77556e-17" rpy="1.5708 -0 0"/>
      <geometry>
        <mesh filename="package://assets/player.stl"/>
      </geometry>
    </collision>
  </link>
  <!-- Joint from rod_2 to player_2 -->
  <joint name="opponent_kicker" type="continuous">
    <origin xyz="-2.77556e-17 1.19349e-15 -0.45" rpy="3.14159 0 0"/>
    <parent link="rod_2"/>
    <child link="player_2"/>
    <axis xyz="0 0 1"/>
    <limit effort="100" velocity="170"/>
  </joint>
  <!-- Joint from main_body to rod_2 -->
  <joint name="opponent_slider" type="prismatic">
    <origin xyz="0.172 -0.45 0.12" rpy="1.5708 -2.396e-19 4.73315e-30"/>
    <parent link="main_body"/>
    <child link="rod_2"/>
    <axis xyz="0 0 1"/>
    <limit effort="100" velocity="15" lower="-0.154" upper="0.154"/>
  </joint>
</robot>
